<mujoco model="spotlike">
  <compiler angle="degree" coordinate="local" inertiafromgeom="true"/>
  <option integrator="RK4" timestep="0.01"/>
  <custom>
    <numeric data="0.0 0.0 0.55 1.0 0.0 0.0 0.0 0.0 1.0 0.0 -1.0 0.0 -1.0 0.0 1.0" name="init_qpos"/>
  </custom>

  <default>
    <joint armature="1" damping="10" frictionloss="0.25" limited="true"/>
    <geom conaffinity="0" condim="3" density="5.0" friction="1 0.5 0.5" margin="0.01" rgba="0.8 0.6 0.4 1"/>

    <default class="geom_def">
        <geom type="capsule"/>
        <default class="thigh">
            <geom size="0.125" rgba="0.55 0.55 0.55 1"/>

            <default class="FRONT_thigh">
                <geom fromto="0 0 0 -0.9 0 -0.8"/>
            </default>
            <default class="BACK_thigh">
                <geom fromto="0 0 0 -0.9 0 -0.8"/>
            </default>
        </default>
        <default class="calf">
            <geom size="0.075" rgba="0.3 0.3 0.3 1"/>

            <default class="FRONT_calf">
                <geom fromto="0 0 0 0.8 0 -1"/>
            </default>
            <default class="BACK_calf">
                <geom fromto="0 0 0 0.8 0 -1"/>
            </default>
        </default>
        <default class="foot">
            <geom pos="0.8 0 -1" size="0.15" type="sphere" rgba="0 1 0 1"/>
        </default>
    </default>

    <default class="knee">
        <joint axis="0 1 0" range="-65 50" type="hinge"/>
    </default>
    <default class="hip_Y">
        <joint axis="0 1 0" range="-25 40" type="hinge"/>
    </default>
    <default class="hip_X">
        <joint type="hinge" range="-45 45"/>
        <default class="L_hip_X">
            <joint axis="1 0 0"/>
        </default>
        <default class="R_hip_X">
            <joint axis="-1 0 0"/>
        </default>
    </default>

  </default>

  <asset>
    <texture builtin="gradient" height="100" rgb1="1 1 1" rgb2="0 0 0" type="skybox" width="100"/>
    <texture builtin="flat" height="1278" mark="cross" markrgb="1 1 1" name="texgeom" random="0.01" rgb1="0.8 0.6 0.4" rgb2="0.8 0.6 0.4" type="cube" width="127"/>
    <texture builtin="checker" height="100" name="texplane" rgb1="0 0 0" rgb2="0.8 0.8 0.8" type="2d" width="100"/>
    <material name="MatPlane" reflectance="0.5" shininess="1" specular="1" texrepeat="60 60" texture="texplane"/>
    <material name="geom" texture="texgeom" texuniform="true"/>
  </asset>

  <worldbody>
    <light cutoff="100" diffuse="1 1 1" dir="-0 0 -1.3" directional="true" exponent="1" pos="0 0 1.3" specular=".1 .1 .1"/>
    <geom conaffinity="1" condim="3" material="MatPlane" name="floor" pos="0 0 0" rgba="0.8 0.9 0.8 1" size="200 40 40" type="plane"/>

    <body name="torso" pos="0 0 2.2">
      <camera name="target" mode="trackcom" pos="0 -4 5" axisangle="1 0 0 35"/>
      <camera name="track" mode="trackcom" pos="0 -8 -0.5" xyaxes="1 0 0 0 0 1"/>

      <geom name="torso_geom" pos="0 0 0" size="1.5 0.4 0.3" type="box"/>
      <!-- connecting body to the world -->
      <joint armature="0" damping="0" limited="false" margin="0.01" name="root" pos="0 0 0" type="free"/> 

      <body name="front" pos="1.2 0 0">
        <geom name="mockup_joints_front" fromto="0 -0.55 0 0 0.55 0" size="0.2" type="capsule"/>
        <body name="FL_thigh" pos="0 -0.6 0">
          <joint class="L_hip_X" name="FL_hip_X"/>
          <joint class="hip_Y" name="FL_hip_Y"/>
          <geom class="FRONT_thigh" name="FL_thigh_geom"/>

          <body name="FL_calf" pos="-0.9 0 -0.8">
            <joint class="knee" name="FL_knee"/>
            <geom class="FRONT_calf" name="FL_calf_geom"/>

            <geom class="foot"/>
          </body>
        </body>

        <body name="FR_thigh" pos="0 +0.6 0">
          <joint class="R_hip_X" name="FR_hip_X"/>
          <joint class="hip_Y" name="FR_hip_Y"/>
          <geom class="FRONT_thigh" name="FR_thigh_geom"/>

          <body name="FR_calf" pos="-0.9 0 -0.8">
            <joint class="knee" name="FR_knee"/>
            <geom class="FRONT_calf" name="FR_calf_geom"/>

            <geom class="foot"/>
          </body>
        </body>
      </body>

      <body name="back" pos="-1.2 0 0">
        <geom name="mockup_joints_back" fromto="0 -0.55 0 0 0.55 0" size="0.2" type="capsule"/>
        <body name="BL_thigh" pos="0 -0.6 0">
          <joint class="L_hip_X" name="BL_hip_X"/>
          <joint class="hip_Y" name="BL_hip_Y"/>
          <geom class="BACK_thigh" name="BL_thigh_geom"/>

          <body name="BL_calf" pos="-0.9 0 -0.8">
            <joint class="knee" name="BL_knee"/>
            <geom class="BACK_calf" name="BL_calf_geom"/>

            <geom class="foot"/>
          </body>
        </body>

        <body name="BR_thigh" pos="0 +0.6 0">
          <joint class="R_hip_X" name="BR_hip_X"/>
          <joint class="hip_Y" name="BR_hip_Y"/>
          <geom class="BACK_thigh" name="BR_thigh_geom"/>

          <body name="BR_calf" pos="-0.9 0 -0.8">
            <joint class="knee" name="BR_knee"/>
            <geom class="BACK_calf" name="BR_calf_geom"/>

            <geom class="foot"/>
          </body>
        </body>
      </body>

      <body name="bottom" pos="0 0 -2.2">
      </body>
    </body>
  </worldbody>
  <actuator>
    <position ctrllimited="true" ctrlrange="-1.0 1.0" joint="FL_hip_X" kp="100"/>
    <position ctrllimited="true" ctrlrange="-1.0 1.0" joint="FL_hip_Y" kp="100"/>
    <position ctrllimited="true" ctrlrange="-1.0 1.0" joint="FL_knee"  kp="100"/>
    <position ctrllimited="true" ctrlrange="-1.0 1.0" joint="FR_hip_X" kp="100"/>
    <position ctrllimited="true" ctrlrange="-1.0 1.0" joint="FR_hip_Y" kp="100"/>
    <position ctrllimited="true" ctrlrange="-1.0 1.0" joint="FR_knee"  kp="100"/>
    <position ctrllimited="true" ctrlrange="-1.0 1.0" joint="BL_hip_X" kp="100"/>
    <position ctrllimited="true" ctrlrange="-1.0 1.0" joint="BL_hip_Y" kp="100"/>
    <position ctrllimited="true" ctrlrange="-1.0 1.0" joint="BL_knee"  kp="100"/>
    <position ctrllimited="true" ctrlrange="-1.0 1.0" joint="BR_hip_X" kp="100"/>
    <position ctrllimited="true" ctrlrange="-1.0 1.0" joint="BR_hip_Y" kp="100"/>
    <position ctrllimited="true" ctrlrange="-1.0 1.0" joint="BR_knee"  kp="100"/>
  </actuator>
</mujoco>
